<robot name="ETB_Test_Jig">
  <link name="base_link"/>
  <link	name="U_shape" >
  </link>
  <link name="middle_arms">
  </link>
  <link name="elbow_link">
  </link>
  <link name="elbow_cylinder">
  </link>
  <link name="head_link">
  </link>
  <link name="servo_head">
  </link>

  <joint name="base_yaw" type="revolute">
    <origin xyz="0 0 32E-3" rpy="0 0 0"/>
    <parent link="base_link" />
    <child link="U_shape" />
    <axis xyz="0 0 -1"/>

  </joint>
  <joint name="mid_arms_pitch" type="revolute">
    <origin xyz="43E-3 0 47E-3" rpy="0 0 0"/>
    <parent link="U_shape" />
    <child link="middle_arms" />1
    <axis xyz="0 1 0"/>11
  </joint>
  <joint name="elbow_pitch" type="revolute">
    <origin xyz="0 0 135E-3" rpy="0 1.57 0" />
    <parent link="middle_arms" />
    <child link="elbow_link" />
    <axis xyz="0 1 0"/>
  </joint>
  <joint name="elbow_rot" type="revolute">
    <origin xyz="0 0 16.7E-3" rpy="0 0 0" />
    <parent link="elbow_link" />
    <child link="elbow_cylinder" />
    <axis xyz="0 0 1"/>

  </joint>
  <joint name="head_pitch" type="revolute">
    <origin xyz="0 0 102E-3" rpy="0 -0.4 0" />
    <parent link="elbow_cylinder" />
    <child link="head_link" />
    <axis xyz="0 1 0"/>
  </joint>
  <joint name="head_rot" type="revolute">
    <origin xyz="0 0 30E-3" rpy="0 0 0" />
    <parent link="head_link" />
    <child link="servo_head" />
    <axis xyz="0 0 1"/>
  </joint>
</robot>


